Workbook

Sheet 페르소나_100
A1: 페르소나ID | B1: 성별 | C1: 연령 | D1: 사는 지역 | E1: 선호하는 숙소 유형 | F1: 소득 수준 | G1: 국내 여행 횟수 | H1: 혼인 유무 | I1: 부양 가족 수 | J1: 직업 | K1: 결제방식 | L1: 방문활동(ACT) | M1: 방문지유형(VIS) | N1: 1번 여행 시 소비 금액 | O1: 주 이동수단 | P1: 여행 목적 | Q1: 여행 일수 | R1: 재방문 의향 점수 | S1: 방문 순서 | T1: 추천 의향 점수 | U1: [참고] 주요 여행지 | V1: [참고] 원본 TRAVEL_ID
A2: P001 | B2: 여 | C2: 30대 | D2: 인천광역시 | E2: 데이터 없음 | F2: 월평균 300만원 ~ 400만원 미만 | G2: 2회 (한달 기준) | H2: 미혼 | I2: 4명 | J2: 전문가 및 관련 종사자 | K2: 카드 일시불 | L2: 취식 | M2: 식당/카페 | N2: 232900 | O2: 자가용(승용/승합/트럭 등등) | P2: 쇼핑 / 역사 유적지 방문 / 시티투어 | Q2: 2 | R2: 3 | S2: 3 | T2: 4 | U2: 경기도 | V2: a_a006408
A3: P002 | B3: 여 | C3: 20대 | D3: 서울특별시 | E3: 데이터 없음 | F3: 소득없음 | G3: 4회 (1년 기준) | H3: 미혼 | I3: 2명 | J3: 학생 | K3: 카드 일시불 | L3: 취식 | M3: 식당/카페 | N3: 34900 | O3: 도보 | P3: 쇼핑 / 드라마 촬영지 방문 / 역사 유적지 방문 | Q3: 2 | R3: 4.6 | S3: 7 | T3: 4.6 | U3: 서울특별시 | V3: a_a007079
A4: P003 | B4: 여 | C4: 30대 | D4: 경기도 | E4: 데이터 없음 | F4: 월평균 300만원 ~ 400만원 미만 | G4: 2회 (1년 기준) | H4: 미혼 | I4: 3명 | J4: 사무 종사자 | K4: 카드 일시불 | L4: 취식 | M4: 자연관광지 | N4: 206800 | O4: 자가용(승용/승합/트럭 등등) | P4: 쇼핑 / 테마파크, 놀이시설, 동/식물원 방문 / Well-ness 여행 | Q4: 2 | R4: 3.6 | S4: 5 | T4: 3.6 | U4: 경기도 | V4: a_a001749
A5: P004 | B5: 여 | C5: 20대 | D5: 경기도 | E5: 데이터 없음 | F5: 월평균 200만원 ~ 300만원 미만 | G5: 1회 (한달 기준) | H5: 미혼 | I5: 1명 | J5: 전문가 및 관련 종사자 | K5: 카드 일시불 | L5: 쇼핑 / 구매 | M5: 식당/카페 | N5: 249700 | O5: 지하철 | P5: 쇼핑 / SNS 인생샷 여행 / 시티투어 | Q5: 2 | R5: 3 | S5: 1 | T5: 2 | U5: 경기도 | V5: a_a002831
A6: P005 | B6: 여 | C6: 20대 | D6: 서울특별시 | E6: 데이터 없음 | F6: 월평균 200만원 ~ 300만원 미만 | G6: 4회 (1년 기준) | H6: 미혼 | I6: 1명 | J6: 사무 종사자 | K6: 카드 일시불 | L6: 취식 | M6: 역, 터미널, 고속도로 휴게소 | N6: 113700 | O6: 자가용(승용/승합/트럭 등등) | P6: Well-ness 여행 / 지역 문화예술/공연/전시시설 관람 / 지역 축제/이벤트 참가 | Q6: 2 | R6: 3.6 | S6: 5 | T6: 3.6 | U6: 데이터 없음 | V6: a_a001034
A7: P006 | B7: 남 | C7: 50대 | D7: 제주특별자치도 | E7: 가족/친지집 | F7: 월평균 100만원 ~ 200만원 미만 | G7: 6회 (1년 기준) | H7: 기혼 | I7: 4명 | J7: 서비스 종사자 | K7: 카드 일시불 | L7: 기타 활동 | M7: 역, 터미널, 고속도로 휴게소 | N7: 410300 | O7: 자가용(승용/승합/트럭 등등) | P7: 쇼핑 | Q7: 3 | R7: 4 | S7: 8 | T7: 4 | U7: 제주특별자치도 | V7: a_a015175
A8: P007 | B8: 남 | C8: 30대 | D8: 경기도 | E8: 기타 | F8: 월평균 200만원 ~ 300만원 미만 | G8: 4회 (1년 기준) | H8: 기혼 | I8: 3명 | J8: 사무 종사자 | K8: 카드 일시불 | L8: 취식 | M8: 식당/카페 | N8: 278086 | O8: 자가용(승용/승합/트럭 등등) | P8: 교육/체험 프로그램 참가 | Q8: 3 | R8: 4.9 | S8: 8 | T8: 5 | U8: 경기도 | V8: a_a001600
A9: P008 | B9: 여 | C9: 30대 | D9: 대구광역시 | E9: 호텔 | F9: 월평균 100만원 ~ 200만원 미만 | G9: 3회 (1년 기준) | H9: 미혼 | I9: 3명 | J9: 서비스 종사자 | K9: 카드 일시불 | L9: 휴식 | M9: 역, 터미널, 고속도로 휴게소 | N9: 377181 | O9: 자가용(승용/승합/트럭 등등) | P9: SNS 인생샷 여행 / 호캉스 여행 / 반려동물 동반 여행 | Q9: 3 | R9: 4.5 | S9: 3 | T9: 4.2 | U9: 경기도 | V9: a_a001851
A10: P009 | B10: 남 | C10: 20대 | D10: 충청남도 | E10: 펜션 | F10: 월평균 300만원 ~ 400만원 미만 | G10: 1회 (한달 기준) | H10: 미혼 | I10: 1명 | J10: 전문가 및 관련 종사자 | K10: 카드 일시불 | L10: 취식 | M10: 역, 터미널, 고속도로 휴게소 | N10: 270000 | O10: 자가용(승용/승합/트럭 등등) | P10: 쇼핑 / 테마파크, 놀이시설, 동/식물원 방문 / Well-ness 여행 | Q10: 3 | R10: 3.5 | S10: 5 | T10: 3.8 | U10: 충청남도 | V10: a_a000670
A11: P010 | B11: 남 | C11: 20대 | D11: 대구광역시 | E11: 모텔/여관 | F11: 월평균 100만원 ~ 200만원 미만 | G11: 3회 (1년 기준) | H11: 미혼 | I11: 1명 | J11: 데이터 없음 | K11: 카드 일시불 | L11: 휴식 | M11: 식당/카페 | N11: 110500 | O11: 지하철 | P11: 테마파크, 놀이시설, 동/식물원 방문 / 역사 유적지 방문 / 시티투어 | Q11: 3 | R11: 3.8 | S11: 5 | T11: 3.9 | U11: 데이터 없음 | V11: a_a000817
A12: P011 | B12: 남 | C12: 30대 | D12: 경기도 | E12: 호텔 | F12: 월평균 400만원 ~ 500만원 미만 | G12: 5회 (1년 기준) | H12: 기혼 | I12: 3명 | J12: 사무 종사자 | K12: 카드 일시불 | L12: 취식 | M12: 식당/카페 | N12: 402300 | O12: 자가용(승용/승합/트럭 등등) | P12: 호캉스 여행 / 인플루언서 따라하기 여행 | Q12: 3 | R12: 4.3 | S12: 4 | T12: 4.3 | U12: 경기도 | V12: a_a006247
A13: P012 | B13: 남 | C13: 40대 | D13: 서울특별시 | E13: 펜션 | F13: 월평균 300만원 ~ 400만원 미만 | G13: 1회 (한달 기준) | H13: 기혼 | I13: 3명 | J13: 전문가 및 관련 종사자 | K13: 카드 일시불 | L13: 체험 활동 / 입장 및 관람 | M13: 식당/카페 | N13: 323250 | O13: 자가용(승용/승합/트럭 등등) | P13: 캠핑 | Q13: 3 | R13: 4 | S13: 2 | T13: 4 | U13: 서울특별시 | V13: b_b000086
... A101: P100 | B101: 여 | C101: 20대 | D101: 경기도 | E101: 데이터 없음 | F101: 월평균 400만원 ~ 500만원 미만 | G101: 2회 (1주일 기준) | H101: 미혼 | I101: 3명 | J101: 전문가 및 관련 종사자 | K101: 카드 일시불 | L101: 취식 | M101: 식당/카페 | N101: 257400 | O101: 자가용(승용/승합/트럭 등등) | P101: 쇼핑 / Well-ness 여행 / SNS 인생샷 여행 | Q101: 4 | R101: 5 | S101: 7 | T101: 5 | U101: 충청북도 | V101: a_a001244

Sheet Sheet1
A1: 페르소나ID | B1: 성별 | C1: 연령 | D1: 사는 지역 | E1: 선호하는 숙소 유형 | F1: 소득 수준 | G1: 국내 여행 횟수 | H1: 혼인 유무 | I1: 부양 가족 수 | J1: 직업 | K1: 결제방식 | L1: 방문활동(ACT) | M1: 방문지유형(VIS) | N1: 1번 여행 시 소비 금액 | O1: 주 이동수단 | P1: 여행 목적 | Q1: 여행 일수 | R1: 재방문 의향 점수 | S1: 방문 순서 | T1: 추천 의향 점수 | U1: [참고] 주요 여행지 | V1: [참고] 원본 TRAVEL_ID
A2: P072 | B2: 여 | C2: 20대 | D2: 경기도 | E2: 호텔 | F2: 월평균 100만원 미만 | G2: 1회 (1년 기준) | H2: 미혼 | I2: 4명 | J2: 판매 종사자 | K2: 카드 일시불 | L2: 취식 | M2: 식당/카페 | N2: 388140 | O2: 도보 | P2: 쇼핑 / 호캉스 여행 / 시티투어 | Q2: 3 | R2: 4 | S2: 10 | T2: 3.8 | U2: 경기도 | V2: a_a000796
A3: P009 | B3: 남 | C3: 20대 | D3: 충청남도 | E3: 펜션 | F3: 월평균 300만원 ~ 400만원 미만 | G3: 1회 (한달 기준) | H3: 미혼 | I3: 1명 | J3: 전문가 및 관련 종사자 | K3: 카드 일시불 | L3: 취식 | M3: 역, 터미널, 고속도로 휴게소 | N3: 270000 | O3: 자가용(승용/승합/트럭 등등) | P3: 쇼핑 / 테마파크, 놀이시설, 동/식물원 방문 / Well-ness 여행 | Q3: 3 | R3: 3.5 | S3: 5 | T3: 3.8 | U3: 충청남도 | V3: a_a000670
A4: P100 | B4: 여 | C4: 20대 | D4: 경기도 | E4: 데이터 없음 | F4: 월평균 400만원 ~ 500만원 미만 | G4: 2회 (1주일 기준) | H4: 미혼 | I4: 3명 | J4: 전문가 및 관련 종사자 | K4: 카드 일시불 | L4: 취식 | M4: 식당/카페 | N4: 257400 | O4: 자가용(승용/승합/트럭 등등) | P4: 쇼핑 / Well-ness 여행 / SNS 인생샷 여행 | Q4: 4 | R4: 5 | S4: 7 | T4: 5 | U4: 충청북도 | V4: a_a001244
A5: P050 | B5: 남 | C5: 20대 | D5: 경기도 | E5: 데이터 없음 | F5: 소득없음 | G5: 1회 (기타 기준) | H5: 미혼 | I5: 5명 | J5: 학생 | K5: 카드 일시불 | L5: 취식 | M5: 역, 터미널, 고속도로 휴게소 | N5: 102200 | O5: 도보 | P5: 시티투어 / 시티투어 / 쇼핑 | Q5: 2 | R5: 4.6 | S5: 8 | T5: 4.6 | U5: 데이터 없음 | V5: a_a005418
A6: P007 | B6: 남 | C6: 30대 | D6: 경기도 | E6: 기타 | F6: 월평균 200만원 ~ 300만원 미만 | G6: 4회 (1년 기준) | H6: 기혼 | I6: 3명 | J6: 사무 종사자 | K6: 카드 일시불 | L6: 취식 | M6: 식당/카페 | N6: 278086 | O6: 자가용(승용/승합/트럭 등등) | P6: 교육/체험 프로그램 참가 | Q6: 3 | R6: 4.9 | S6: 8 | T6: 5 | U6: 경기도 | V6: a_a001600

Sheet 요약_분포
A1: 페르소나 100명 분포 요약
A2: 모든 수치는 페르소나_100 시트를 참조하는 COUNTIF/AVERAGE 수식입니다. 표를 편집하면 자동 갱신됩니다.
A4: 연령대
A5: 항목 | B5: 인원(명) | C5: 비중
A6: 30대 | B6: =COUNTIF(페르소나_100!$C$2:$C$101,"30대") -> 39 | C6: =B6/100 -> 0.39
A7: 20대 | B7: =COUNTIF(페르소나_100!$C$2:$C$101,"20대") -> 35 | C7: =B7/100 -> 0.35
A8: 40대 | B8: =COUNTIF(페르소나_100!$C$2:$C$101,"40대") -> 17 | C8: =B8/100 -> 0.17
A9: 50대 | B9: =COUNTIF(페르소나_100!$C$2:$C$101,"50대") -> 6 | C9: =B9/100 -> 0.06
A10: 60대 | B10: =COUNTIF(페르소나_100!$C$2:$C$101,"60대") -> 3 | C10: =B10/100 -> 0.03
A12: 거주 지역(시도)
A13: 항목 | B13: 인원(명) | C13: 비중
A14: 서울특별시 | B14: =COUNTIF(페르소나_100!$D$2:$D$101,"서울특별시") -> 41 | C14: =B14/100 -> 0.41
A15: 경기도 | B15: =COUNTIF(페르소나_100!$D$2:$D$101,"경기도") -> 31 | C15: =B15/100 -> 0.31
A16: 인천광역시 | B16: =COUNTIF(페르소나_100!$D$2:$D$101,"인천광역시") -> 6 | C16: =B16/100 -> 0.06
A17: 경상남도 | B17: =COUNTIF(페르소나_100!$D$2:$D$101,"경상남도") -> 4 | C17: =B17/100 -> 0.04
A18: 대구광역시 | B18: =COUNTIF(페르소나_100!$D$2:$D$101,"대구광역시") -> 3 | C18: =B18/100 -> 0.03
A19: 강원도 | B19: =COUNTIF(페르소나_100!$D$2:$D$101,"강원도") -> 3 | C19: =B19/100 -> 0.03
A20: 제주특별자치도 | B20: =COUNTIF(페르소나_100!$D$2:$D$101,"제주특별자치도") -> 2 | C20: =B20/100 -> 0.02
A21: 충청남도 | B21: =COUNTIF(페르소나_100!$D$2:$D$101,"충청남도") -> 2 | C21: =B21/100 -> 0.02
A22: 충청북도 | B22: =COUNTIF(페르소나_100!$D$2:$D$101,"충청북도") -> 2 | C22: =B22/100 -> 0.02
A23: 대전광역시 | B23: =COUNTIF(페르소나_100!$D$2:$D$101,"대전광역시") -> 2 | C23: =B23/100 -> 0.02
A24: 전라남도 | B24: =COUNTIF(페르소나_100!$D$2:$D$101,"전라남도") -> 2 | C24: =B24/100 -> 0.02
A25: 울산광역시 | B25: =COUNTIF(페르소나_100!$D$2:$D$101,"울산광역시") -> 1 | C25: =B25/100 -> 0.01
A26: 경상북도 | B26: =COUNTIF(페르소나_100!$D$2:$D$101,"경상북도") -> 1 | C26: =B26/100 -> 0.01
A28: 숙소 유형
A29: 항목 | B29: 인원(명) | C29: 비중
A30: 데이터 없음 | B30: =COUNTIF(페르소나_100!$E$2:$E$101,"데이터 없음") -> 61 | C30: =B30/100 -> 0.61
A31: 호텔 | B31: =COUNTIF(페르소나_100!$E$2:$E$101,"호텔") -> 15 | C31: =B31/100 -> 0.15
A32: 펜션 | B32: =COUNTIF(페르소나_100!$E$2:$E$101,"펜션") -> 6 | C32: =B32/100 -> 0.06
A33: 모텔/여관 | B33: =COUNTIF(페르소나_100!$E$2:$E$101,"모텔/여관") -> 4 | C33: =B33/100 -> 0.04
A34: 야영(캠핑,글램핑등) | B34: =COUNTIF(페르소나_100!$E$2:$E$101,"야영(캠핑,글램핑등)") -> 4 | C34: =B34/100 -> 0.04
A35: 콘도미니엄/리조트 | B35: =COUNTIF(페르소나_100!$E$2:$E$101,"콘도미니엄/리조트") -> 3 | C35: =B35/100 -> 0.03
A36: 게스트하우스 | B36: =COUNTIF(페르소나_100!$E$2:$E$101,"게스트하우스") -> 3 | C36: =B36/100 -> 0.03
A37: 가족/친지집 | B37: =COUNTIF(페르소나_100!$E$2:$E$101,"가족/친지집") -> 1 | C37: =B37/100 -> 0.01
A38: 기타 | B38: =COUNTIF(페르소나_100!$E$2:$E$101,"기타") -> 1 | C38: =B38/100 -> 0.01
A39: 자연휴양림내 시설 | B39: =COUNTIF(페르소나_100!$E$2:$E$101,"자연휴양림내 시설") -> 1 | C39: =B39/100 -> 0.01
A40: 무박 여행 | B40: =COUNTIF(페르소나_100!$E$2:$E$101,"무박 여행") -> 1 | C40: =B40/100 -> 0.01
A42: 직업
A43: 항목 | B43: 인원(명) | C43: 비중
A44: 사무 종사자 | B44: =COUNTIF(페르소나_100!$J$2:$J$101,"사무 종사자") -> 31 | C44: =B44/100 -> 0.31
...

Sheet 생성방법_한계
A1: 페르소나 100 생성 방법 · 전제 · 한계
A2: 작성일 2026-07-31 / 파워BI레인저 데이터분석 프로젝트
A4: 1. 데이터 출처
A5: 원천: 프로젝트 제공 국내 여행 데이터셋(tn_travel, tn_traveller_master, tn_visit_area_info,
A6: tn_activity_his, tn_move_his, tn_lodge/activity/mvmn/adv_consume_his, tc_codea/codeb, tc_sgg)
A7: 수집 기간: 2022-08-04 ~ 2022-11-14 (여행 시작일~종료일 기준)
A8: 모집단: 여행 3,200건 / 여행객 3,200명 (1인 1여행)
A10: 2. 생성 방식 — "임의 창작"이 아니라 "실제 레코드 디코딩"
A11: 요청은 임의 페르소나였으나, 값을 지어내면 이후 분석과 수치가 어긋나므로
A12: 실제 여행 레코드 100건을 뽑아 코드값을 한글 라벨로 변환하는 방식으로 만들었습니다.
A13: 따라서 컬럼 간 조합(예: 20대·학생·소득없음·도보)이 현실적으로 유지됩니다.
A15: 표본 필터: 소비금액>0, 만족도 평가 1건 이상, 방문지유형·방문활동·이동수단 모두 확인 가능
... A54: 목적 파악에는 최빈값 대신 체류시간(RESIDENCE_TIME_MIN)이나 소비액 기준 집계가 더 적절합니다.
